Workbook

Sheet Header & Notes
B6: 1 | C6: ID Bank
B8: 2 | C8: Nama bank | J8: Bank x
B10: 3 | C10: Tanggal pelaporan | J10: MM/DD/YYYY
B12: 4 | C12: Mata uang denominasi (select from list) | J12: IDR
B14: 5 | C14: Satuan | J14: Jutaan

Sheet Dashboard
H6: Analysis
H9: ='Header & Notes'!J8&" - "&(TEXT('Header & Notes'!J10,"DD/MM/YYYY")) -> Bank x - MM/DD/YYYY
H11: Day | K11: =TEXT(K12,"ddd") -> MM/DD/YYYY | L11: =TEXT(L12,"ddd") -> #VALUE! | M11: =TEXT(M12,"ddd") -> #VALUE!
H12: Date | K12: ='Header & Notes'!J10 -> MM/DD/YYYY | L12: =K12+1 -> #VALUE! | M12: =K12+1 -> #VALUE! | N12: =M12+1 -> #VALUE! | O12: =N12+1 -> #VALUE! | P12: =O12+1 -> #VALUE! | Q12: =P12+1 -> #VALUE! | R12: =Q12+1 -> #VALUE! | S12: =R12+1 -> #VALUE! | T12: =S12+1 -> #VALUE! | U12: =T12+1 -> #VALUE! | ... AP12: =AO12+1 -> #VALUE! | AQ12: =AP12+7 -> #VALUE! | AR12: =EOMONTH($K12,2) -> #VALUE! | AS12: =EOMONTH($K12,3) -> #VALUE! | AT12: =EOMONTH($K12,4) -> #VALUE! | AU12: =EOMONTH($K12,5) -> #VALUE! | AV12: =EOMONTH($K12,6) -> #VALUE! | AW12: =EOMONTH($K12,9) -> #VALUE! | AX12: =EOMONTH($K12,12) -> #VALUE! | AY12: =EOMONTH($K12,24) -> #VALUE! | AZ12: =EOMONTH($K12,60) -> #VALUE! | BA12: =EOMONTH($K12,72) -> #VALUE!
K13: Initial stock | L13: Tanpa Maturitas (Open) | M13: O/N | N13: Hari-2 | O13: Hari-3 | P13: Hari-4 | Q13: Hari-5 | R13: Hari-6 | S13: Hari-7 | T13: Hari-8 | U13: Hari-9 | V13: Hari-10 | W13: Hari-11 | X13: Hari-12 | Y13: Hari-13 | Z13: Hari-14 | AA13: Hari-15 | AB13: Hari-16 | AC13: Hari-17 | AD13: Hari-18 | AE13: Hari-19 | AF13: Hari-20 | AG13: Hari-21 | AH13: Hari-22 | AI13: Hari-23 | AJ13: Hari-24 | AK13: Hari-25 | AL13: Hari-26 | AM13: Hari-27 | AN13: Hari-28 | AO13: Hari-29 | AP13: Hari-30 | AQ13: > mg 4 s.d. mg 5 | AR13: > mg 5 s.d. 2 bln | AS13: > 2 bln s.d 3 bln | AT13: > 3 bln s.d 4 bln | AU13: > 4 bln s.d 5 bln | AV13: > 5 bln s.d 6 bln | AW13: > 6 bln s.d. 9 bln | AX13: > 9 bln s.d. 12 bln | AY13: > 12 bln s.d. 2 thn | AZ13: > 2 thn s.d. 5 thn | BA13: > 5 thn
M14: 1 | N14: 2 | O14: 3 | P14: 4 | Q14: 5 | R14: 6 | S14: 7 | T14: 8 | U14: 9 | V14: 10 | W14: 11 | X14: 12 | Y14: 13 | Z14: 14 | AA14: 15 | AB14: 16 | AC14: 17 | AD14: 18 | AE14: 19 | AF14: 20 | AG14: 21 | AH14: 22 | AI14: 23 | AJ14: 24 | AK14: 25 | AL14: 26 | AM14: 27 | AN14: 28 | AO14: 29 | AP14: 30
M15: =M12-$K12 -> #VALUE! | N15: =N12-$K12 -> #VALUE! | O15: =O12-$K12 -> #VALUE! | P15: =P12-$K12 -> #VALUE! | Q15: =Q12-$K12 -> #VALUE! | R15: =R12-$K12 -> #VALUE! | S15: =S12-$K12 -> #VALUE! | T15: =T12-$K12 -> #VALUE! | ... BA15: =BA12-$K12 -> #VALUE!
H16: Granular LCR / Benchmark
H17: HQLA (posisi awal) | K17: ='SPM Skenario Dasar'!K86+'SPM Skenario Dasar'!K87+'SPM Skenario Dasar'!K88+'SPM Skenario Dasar'!K92+'SPM Skenario Dasar'!K95 -> 0 | L17: =$K17 -> 0 | M17: =$K17 -> 0 | N17: =$K17 -> 0 | O17: =$K17 -> 0 | P17: =$K17 -> 0 | Q17: =$K17 -> 0 | R17: =$K17 -> 0 | S17: =$K17 -> 0 | ... BA17: =$K17 -> 0
H19: Arus masuk bruto | L19: ='SPM Skenario Dasar'!L82 -> 0 | M19: ='SPM Skenario Dasar'!M82 -> 0 | N19: ='SPM Skenario Dasar'!N82 -> 0 | O19: ='SPM Skenario Dasar'!O82 -> 0 | P19: ='SPM Skenario Dasar'!P82 -> 0 | Q19: ='SPM Skenario Dasar'!Q82 -> 0 | R19: ='SPM Skenario Dasar'!R82 -> 0 | S19: ='SPM Skenario Dasar'!S82 -> 0 | ... BA19: ='SPM Skenario Dasar'!BA82 -> 0
H20: Arus keluar bruto | L20: =SUM('SPM Skenario Dasar'!L51,'SPM Skenario Dasar'!L108,'SPM Skenario Dasar'!L115,'SPM Skenario Dasar'!L118,'SPM Skenario Dasar'!L123,'SPM Skenario Dasar'!L128,'SPM Skenario Dasar'!L132) -> 0 | M20: =SUM('SPM Skenario Dasar'!M51,'SPM Skenario Dasar'!M108,'SPM Skenario Dasar'!M115,'SPM Skenario Dasar'!M118,'SPM Skenario Dasar'!M123,'SPM Skenario Dasar'!M128,'SPM Skenario Dasar'!M132) -> 0 | N20: =SUM('SPM Skenario Dasar'!N51,'SPM Skenario Dasar'!N108,'SPM Skenario Dasar'!N115,'SPM Skenario Dasar'!N118,'SPM Skenario Dasar'!N123,'SPM Skenario Dasar'!N128,'SPM Skenario Dasar'!N132) -> 0 | O20: =SUM('SPM Skenario Dasar'!O51,'SPM Skenario Dasar'!O108,'SPM Skenario Dasar'!O115,'SPM Skenario Dasar'!O118,'SPM Skenario Dasar'!O123,'SPM Skenario Dasar'!O128,'SPM Skenario Dasar'!O132) -> 0 | P20: =SUM('SPM Skenario Dasar'!P51,'SPM Skenario Dasar'!P108,'SPM Skenario Dasar'!P115,'SPM Skenario Dasar'!P118,'SPM Skenario Dasar'!P123,'SPM Skenario Dasar'!P128,'SPM Skenario Dasar'!P132) -> 0 | Q20: =SUM('SPM Skenario Dasar'!Q51,'SPM Skenario Dasar'!Q108,'SPM Skenario Dasar'!Q115,'SPM Skenario Dasar'!Q118,'SPM Skenario Dasar'!Q123,'SPM Skenario Dasar'!Q128,'SPM Skenario Dasar'!Q132) -> 0 | R20: =SUM('SPM Skenario Dasar'!R51,'SPM Skenario Dasar'!R108,'SPM Skenario Dasar'!R115,'SPM Skenario Dasar'!R118,'SPM Skenario Dasar'!R123,'SPM Skenario Dasar'!R128,'SPM Skenario Dasar'!R132) -> 0 | S20: =SUM('SPM Skenario Dasar'!S51,'SPM Skenario Dasar'!S108,'SPM Skenario Dasar'!S115,'SPM Skenario Dasar'!S118,'SPM Skenario Dasar'!S123,'SPM Skenario Dasar'!S128,'SPM Skenario Dasar'!S132) -> 0 | ... BA20: =SUM('SPM Skenario Dasar'!BA51,'SPM Skenario Dasar'!BA108,'SPM Skenario Dasar'!BA115,'SPM Skenario Dasar'!BA118,'SPM Skenario Dasar'!BA123,'SPM Skenario Dasar'!BA128,'SPM Skenario Dasar'!BA132) -> 0
H21: Kumulatif arus masuk bruto | L21: =L19 -> 0 | M21: =M19+L21 -> 0 | N21: =N19+M21 -> 0 | O21: =O19+N21 -> 0 | P21: =P19+O21 -> 0 | Q21: =Q19+P21 -> 0 | R21: =R19+Q21 -> 0 | S21: =S19+R21 -> 0 | T21: =T19+S21 -> 0 | ... BA21: =BA19+AZ21 -> 0
H22: Kumulatif arus keluar bruto | L22: =L20 -> 0 | M22: =M20+L22 -> 0 | N22: =N20+M22 -> 0 | O22: =O20+N22 -> 0 | P22: =P20+O22 -> 0 | Q22: =Q20+P22 -> 0 | R22: =R20+Q22 -> 0 | S22: =S20+R22 -> 0 | T22: =T20+S22 -> 0 | ... BA22: =BA20+AZ22 -> 0
H23: FX swap arus masuk (memo) | L23: ='SPM Skenario Dasar'!L76 -> 0 | M23: ='SPM Skenario Dasar'!M76 -> 0 | N23: ='SPM Skenario Dasar'!N76 -> 0 | O23: ='SPM Skenario Dasar'!O76 -> 0 | P23: ='SPM Skenario Dasar'!P76 -> 0 | Q23: ='SPM Skenario Dasar'!Q76 -> 0 | R23: ='SPM Skenario Dasar'!R76 -> 0 | S23: ='SPM Skenario Dasar'!S76 -> 0 | ... BA23: ='SPM Skenario Dasar'!BA76 -> 0
H24: FX swap arus keluar (memo) | L24: ='SPM Skenario Dasar'!L48 -> 0 | M24: ='SPM Skenario Dasar'!M48 -> 0 | N24: ='SPM Skenario Dasar'!N48 -> 0 | O24: ='SPM Skenario Dasar'!O48 -> 0 | P24: ='SPM Skenario Dasar'!P48 -> 0 | Q24: ='SPM Skenario Dasar'!Q48 -> 0 | R24: ='SPM Skenario Dasar'!R48 -> 0 | S24: ='SPM Skenario Dasar'!S48 -> 0 | ... BA24: ='SPM Skenario Dasar'!BA48 -> 0
H25: Add-on Pillar 2 | L25: =('SPM Skenario Dasar'!L180) -> 0 | M25: =('SPM Skenario Dasar'!M180) -> 0 | N25: =('SPM Skenario Dasar'!N180) -> 0 | O25: =('SPM Skenario Dasar'!O180) -> 0 | P25: =('SPM Skenario Dasar'!P180) -> 0 | Q25: =('SPM Skenario Dasar'!Q180) -> 0 | R25: =('SPM Skenario Dasar'!R180) -> 0 | S25: =('SPM Skenario Dasar'!S180) -> 0 | ... BA25: =('SPM Skenario Dasar'!BA180) -> 0
H26: Kumulatif arus keluar bruto (incl. Pillar 2) | L26: =L22+L25 -> 0 | M26: =M22+SUM($L25:M25) -> 0 | N26: =N22+SUM($L25:N25) -> 0 | O26: =O22+SUM($L25:O25) -> 0 | P26: =P22+SUM($L25:P25) -> 0 | Q26: =Q22+SUM($L25:Q25) -> 0 | R26: =R22+SUM($L25:R25) -> 0 | S26: =S22+SUM($L25:S25) -> 0 | T26: =T22+SUM($L25:T25) -> 0 | ... BA26: =BA22+SUM($L25:BA25) -> 0
H27: Kumulatif arus netto (incl. Pillar 2) | L27: =L21+L26 -> 0 | M27: =M21+M26 -> 0 | N27: =N21+N26 -> 0 | O27: =O21+O26 -> 0 | P27: =P21+P26 -> 0 | Q27: =Q21+Q26 -> 0 | R27: =R21+R26 -> 0 | S27: =S21+S26 -> 0 | ... BA27: =BA21+BA26 -> 0
H28: Kumulatif arus netto (excl. Pillar 2) | L28: =L22+L21 -> 0 | M28: =M22+M21 -> 0 | N28: =N22+N21 -> 0 | O28: =O22+O21 -> 0 | P28: =P22+P21 -> 0 | Q28: =Q22+Q21 -> 0 | R28: =R22+R21 -> 0 | S28: =S22+S21 -> 0 | ... BA28: =BA22+BA21 -> 0
H29: Posisi likuiditas kumulatif (HQLA + arus masuk - [arus keluar + P2]) | L29: =L17+L27 -> 0 | M29: =M17+M27 -> 0 | N29: =N17+N27 -> 0 | O29: =O17+O27 -> 0 | P29: =P17+P27 -> 0 | Q29: =Q17+Q27 -> 0 | R29: =R17+R27 -> 0 | S29: =S17+S27 -> 0 | ... BA29: =BA17+BA27 -> 0
H30: LCR (Calculated) | L30: =K17/(ABS(AP22)-MIN(AP21,ABS(AP22)*75%)) -> #DIV/0!
H31: LCR (Pillar 2) | L31: =K17/(ABS(AP26)-MIN(AP21,ABS(AP26)*75%)) -> #DIV/0!
H32: Target LCR | L32: =(ABS(AP26)-MIN(AP21,ABS(AP26)*75%))/(ABS(AP22)-MIN(AP21,ABS(AP22)*75%)) -> #DIV/0!
H34: Granular LCR stress (30d)
H35: Posisi likuiditas netto terkecil (dalam 1 bln ke depan) | K35: =MIN(Dashboard!M$29:AP$29) -> 0
H36: Hari atau bucket waktu di mana posisi likuiditas netto terkecil (dalam 1 bln ke depan) | K36: =INDEX(Dashboard!$M$13:$AP$13,1,MATCH(K35,Dashboard!M29:AP29,0)) -> O/N
H37: Kumulatif arus kas keluar tertinggi (arus kas dalam 1 bln tanpa HQLA) | K37: =MIN(Dashboard!M$27:AP$27) -> 0
H38: Posisi likuiditas netto terkecil (arus kas + HQLA, dalam 15 hari) | K38: =MIN(M$29:AA$29) -> 0
H39: Tanggal kegagalan likuiditas | K39: =IF(SUM(Dashboard!M$39:AP$39)>0,INDEX(Dashboard!M$12:AP$12,1,MATCH(1,Dashboard!M$39:AP$39,0)),"Di luar zona 30h") -> Di luar zona 30h | L39: =IF(Dashboard!L29>=0,0,1) -> 0 | M39: =IF(Dashboard!M29>=0,0,1) -> 0 | N39: =IF(Dashboard!N29>=0,0,1) -> 0 | O39: =IF(Dashboard!O29>=0,0,1) -> 0 | P39: =IF(Dashboard!P29>=0,0,1) -> 0 | Q39: =IF(Dashboard!Q29>=0,0,1) -> 0 | R39: =IF(Dashboard!R29>=0,0,1) -> 0 | S39: =IF(Dashboard!S29>=0,0,1) -> 0 | ... BA39: =IF(Dashboard!BA29>=0,0,1) -> 0
H40: Survival period | K40: =IF(K39="Di luar zona 30h",">30 hari",K39-Dashboard!K$12-1 & " hari") -> >30 hari
H41: Posisi likuiditas netto pada saat kegagalan likuiditas | K41: =IF(SUM(Dashboard!M$39:AP$39)>0,INDEX(Dashboard!M$29:AP$29,1,MATCH(1,Dashboard!M$39:AP$39,0)),"N/A") -> N/A
H43: Benchmark Stress (3 bulan)
H44: Posisi likuiditas netto terkecil (dalam 3 bln ke depan) | K44: =MIN(Dashboard!M$29:AS$29) -> 0
H45: Hari atau bucket waktu di mana posisi likuiditas netto terkecil (dalam 3 bln ke depan) | K45: =INDEX(Dashboard!$M$13:$AS$13,1,MATCH(K44,Dashboard!M29:AS29,0)) -> O/N
H46: Kumulatif arus kas keluar tertinggi (arus kas dalam 3 bln tanpa HQLA) | K46: =MIN(Dashboard!M$27:AQ$27) -> 0
H47: Posisi likuiditas netto terkecil (arus kas + HQLA, dalam 2 bln ke depan) | K47: =MIN(M$29:AR$29) -> 0
H48: Tanggal kegagalan likuiditas | K48: =IF(SUM(Dashboard!M$48:AS$48)>0,INDEX(Dashboard!M$12:AS$12,1,MATCH(1,Dashboard!M$48:AS$48,0)),"Di luar zona 92h") -> Di luar zona 92h | L48: =IF(Dashboard!L29>=0,0,1) -> 0 | M48: =IF(Dashboard!M29>=0,0,1) -> 0 | N48: =IF(Dashboard!N29>=0,0,1) -> 0 | O48: =IF(Dashboard!O29>=0,0,1) -> 0 | P48: =IF(Dashboard!P29>=0,0,1) -> 0 | Q48: =IF(Dashboard!Q29>=0,0,1) -> 0 | R48: =IF(Dashboard!R29>=0,0,1) -> 0 | S48: =IF(Dashboard!S29>=0,0,1) -> 0 | ... BA48: =IF(Dashboard!BA29>=0,0,1) -> 0
H49: Survival period | K49: =IF(K48="Di luar zona 92h",">92 days",K48-Dashboard!K$12-1 &" hari") -> >92 days
H50: Posisi likuiditas netto pada saat kegagalan likuiditas | K50: =IF(SUM(Dashboard!M$48:AS$48)>0,INDEX(Dashboard!M$29:AS$29,1,MATCH(1,Dashboard!M$48:AS$48,0)),"N/A") -> N/A
K52: 0 | M52: 0 | N52: 0 | O52: 0 | P52: 0 | AL52: 0 | AM52: 0 | AN52: 0 | AO52: 0
...

Sheet Input Bank
BA10: (Dalam Jutaan Rupiah)
N12: =M12+1 -> 1 | O12: =N12+1 -> 2 | P12: =O12+1 -> 3 | Q12: =P12+1 -> 4 | R12: =Q12+1 -> 5 | S12: =R12+1 -> 6 | AQ12: =#REF!+7 -> #REF! | AR12: =AQ12+ROUNDDOWN(21/2,0) -> #REF! | AS12: =AR12+30/2 -> #REF! | AT12: =AS12+30/2 -> #REF! | AU12: =AT12+30/2 -> #REF! | AV12: =AU12+30/2 -> #REF! | AW12: =AV12+92/2 -> #REF! | AX12: =AW12+92/2 -> #REF! | AY12: =AX12+ROUNDDOWN(365/2,0) -> #REF! | AZ12: =AY12+ROUNDDOWN(3*365/2,) -> #REF! | BA12: =AZ12+3650/2 -> #REF!
G13: Kode | H13: Baris | I13: Item | J13: Bobot LCR | K13: Stok Awal | L13: Tanpa Maturitas (Open) | M13: Overnight (selain Open) | N13: Hari-2 | O13: Hari-3 | P13: ... | Q13: Hari-5 | R13: Hari-6 | S13: Hari-7 | T13: Hari-8 | U13: Hari-9 | V13: Hari-10 | W13: Hari-11 | X13: Hari-12 | Y13: Hari-13 | Z13: Hari-14 | AA13: Hari-15 | AB13: Hari-16 | AC13: Hari-17 | AD13: Hari-18 | AE13: Hari-19 | AF13: Hari-20 | AG13: Hari-21 | AH13: Hari-22 | AI13: Hari-23 | AJ13: Hari-24 | AK13: Hari-25 | AL13: Hari-26 | AM13: Hari-27 | AN13: Hari-28 | AO13: Hari-29 | AP13: Hari-30 | AQ13: > Minggu 4 s.d. Minggu 5 | AR13: > Minggu 5 s.d. 2 Bulan | AS13: > 2 Bulan s.d 3 Bulan | AT13: > 3 Bulan s.d 4 Bulan | AU13: > 4 Bulan s.d 5 Bulan | AV13: > 5 Bulan s.d 6 Bulan | AW13: > 6 Bulan s.d. 9 Bulan | AX13: > 9 Bulan s.d. 12 Bulan | AY13: > 12 Bulan s.d. 2 Bulan | AZ13: > 2 Tahun s.d. 5 Tahun | BA13: > 5 Tahun
G14: 001 | H14: 1 | I14: ARUS KAS KELUAR
G15: 002 | H15: 1.1 | I15: Kewajiban yang berasal dari simpanan yang diterima | L15: =SUM(L16:L30) -> 0 | M15: =SUM(M16:M30) -> 0 | N15: =SUM(N16:N30) -> 0 | O15: =SUM(O16:O30) -> 0 | P15: =SUM(P16:P30) -> 0 | Q15: =SUM(Q16:Q30) -> 0 | R15: =SUM(R16:R30) -> 0 | S15: =SUM(S16:S30) -> 0 | ... BA15: =SUM(BA16:BA30) -> 0
G16: 003 | H16: 1.1.1 | I16: Simpanan stabil dari Nasabah Perorangan | J16: 0.05
G17: 004 | H17: 1.1.2 | I17: Simpanan kurang stabil dari Nasabah Perorangan yang dijamin LPS | J17: 0.1
G18: 005 | H18: 1.1.3 | I18: Simpanan kurang stabil Nasabah Perorangan yang tidak dijamin LPS | J18: 0.1
G19: 006 | H19: 1.1.4 | I19: Pendanaan Stabil dari Nasabah Usaha Mikro dan Usaha Kecil | J19: 0.05
G20: 007 | H20: 1.1.5 | I20: Pendanaan kurang Stabil dari Nasabah Usaha Mikro dan Usaha Kecil yang dijamin LPS | J20: 0.1
G21: 008 | H21: 1.1.6 | I21: Pendanaan kurang Stabil dari Nasabah Usaha Mikro dan Usaha Kecil yang tidak dijamin LPS | J21: 0.1
G22: 009 | H22: 1.1.7 | I22: Simpanan operasional nasabah korporasi yang dijamin LPS | J22: 0.05
G23: 010 | H23: 1.1.8 | I23: Simpanan operasional nasabah korporasi yang tidak dijamin LPS | J23: 0.25
G24: 011 | H24: 1.1.9 | I24: Penarikan Simpanan Non-Operasional dan/atau kewajiban lainnya yang bersifat non-operasional dari:
G25: 012 | H25: 1.1.10 | I25: Bank | J25: 1
G26: 013 | H26: 1.1.11 | I26: LJK lainnya | J26: 1
G27: 014 | H27: 1.1.12 | I27: Korporasi non-finansial yang dijamin LPS | J27: 0.2
G28: 015 | H28: 1.1.13 | I28: Korporasi non-finansial yang tidak dijamin LPS | J28: 0.4
G29: 016 | H29: 1.1.14 | I29: Pemerintah pusat, Bank Indonesia, multilateral, dan entitas publik yang dijamin LPS | J29: 0.2
G30: 017 | H30: 1.1.15 | I30: Pemerintah pusat, Bank Indonesia, multilateral, dan entitas publik yang tidak dijamin LPS | J30: 0.4
G31: 018 | H31: 1.2 | I31: Kewajiban terkait efek yang diterbitkan | L31: =SUM(L32:L33) -> 0 | M31: =SUM(M32:M33) -> 0 | N31: =SUM(N32:N33) -> 0 | O31: =SUM(O32:O33) -> 0 | P31: =SUM(P32:P33) -> 0 | Q31: =SUM(Q32:Q33) -> 0 | R31: =SUM(R32:R33) -> 0 | S31: =SUM(S32:S33) -> 0 | ... BA31: =SUM(BA32:BA33) -> 0
G32: 019 | H32: 1.2.1 | I32: Surat berharga berupa surat utang yang diterbitkan Bank tanpa agunan | J32: 1
G33: 020 | H33: 1.2.2 | I33: Lainnya | J33: 1
G34: 021 | H34: 1.3 | I34: Pendanaan dengan agunan (secured funding) | L34: =SUM(L35,L42) -> 0 | M34: =SUM(M35,M42) -> 0 | N34: =SUM(N35,N42) -> 0 | O34: =SUM(O35,O42) -> 0 | P34: =SUM(P35,P42) -> 0 | Q34: =SUM(Q35,Q42) -> 0 | R34: =SUM(R35,R42) -> 0 | S34: =SUM(S35,S42) -> 0 | ... BA34: =SUM(BA35,BA42) -> 0
G35: 022 | H35: 1.3.1 | I35: Kewajiban timbul dari secured funding atau transaksi pasar modal dengan pihak lawan selain Bank Indonesia: | L35: =SUM(L36:L41) -> 0 | M35: =SUM(M36:M41) -> 0 | N35: =SUM(N36:N41) -> 0 | O35: =SUM(O36:O41) -> 0 | P35: =SUM(P36:P41) -> 0 | Q35: =SUM(Q36:Q41) -> 0 | R35: =SUM(R36:R41) -> 0 | S35: =SUM(S36:S41) -> 0 | ... BA35: =SUM(BA36:BA41) -> 0
G36: 023 | H36: 1.3.2 | I36: Transaksi dilakukan dengan agunan HQLA Level 1 | J36: 0
G37: 024 | H37: 1.3.3 | I37: Transaksi dilakukan dengan agunan HQLA Level 2A | J37: 0.15
G38: 025 | H38: 1.3.4 | I38: Transaksi dilakukan dengan Pemerintah Pusat atau entitas sektor publik yang memiliki bobot risiko paling tinggi 20% atau bank pembangunan multilateral, dengan agunan selain HQLA Level 1 atau HQLA Level 2A | J38: 0.25
G39: 026 | H39: 1.3.5 | I39: Transaksi dilakukan dengan agunan HQLA Level 2B berupa EBA | J39: 0.25
G40: 027 | H40: 1.3.6 | I40: Transaksi dilakukan dengan agunan HQLA Level 2B berupa selain EBA | J40: 0.5
G41: 028 | H41: 1.3.7 | I41: Transaksi dilakukan dengan agunan selain HQLA | J41: 1
G42: 029 | H42: 1.3.8 | I42: Kewajiban timbul dari secured funding atau transaksi pasar modal dengan Bank Indonesia sebagai pihak lawan: | L42: =SUM(L43:L47) -> 0 | M42: =SUM(M43:M47) -> 0 | N42: =SUM(N43:N47) -> 0 | O42: =SUM(O43:O47) -> 0 | P42: =SUM(P43:P47) -> 0 | Q42: =SUM(Q43:Q47) -> 0 | R42: =SUM(R43:R47) -> 0 | S42: =SUM(S43:S47) -> 0 | ... BA42: =SUM(BA43:BA47) -> 0
G43: 030 | H43: 1.3.9 | I43: Transaksi dilakukan dengan agunan HQLA Level 1 | J43: 0
G44: 031 | H44: 1.3.10 | I44: Transaksi dilakukan dengan agunan HQLA Level 2A | J44: 0
G45: 032 | H45: 1.3.11 | I45: Transaksi dilakukan dengan agunan HQLA Level 2B berupa EBA | J45: 0
G46: 033 | H46: 1.3.12 | I46: Transaksi dilakukan dengan agunan HQLA Level 2B berupa selain EBA | J46: 0
G47: 034 | H47: 1.3.13 | I47: Transaksi dilakukan dengan agunan selain HQLA | J47: 0
G48: 035 | H48: 1.4 | I48: FX-swaps jatuh tempo | J48: 1
G49: 036 | H49: 1.5 | I49: Arus kas keluar lainnya terkait transaksi derivatif selain 1.4 | J49: 1
G50: 037 | H50: 1.6 | I50: Arus kas keluar lainnya | J50: 1
...

Sheet Bobot
T9: Scenario 1 | W9: Scenario 1 | Z9: Scenario 1
F11: Kode | G11: Baris | H11: Item | I11: LCR weight | O11: Skenario Dasar | P11: Tenorisasi | T11: Skenario Bank 1 | W11: Skenario Bank 2 | Z11: Skenario Bank 3
I12: Input dari Bank | J12: Input dari Bank atau standar LCR bila input Bank kosong | K12: Supervisory range | M12: Bobot bila Input Pengawas diterapkan
K13: Standar minimum | L13: Standar maksimum | O13: EXPECTED WEIGHT / Standard weight | P13: 1 = Tenorised across 30 days | T13: open | U13: term | W13: open | X13: term | Z13: open | AA13: term
F14: 001 | G14: 1 | H14: ARUS KAS KELUAR
F15: 002 | G15: 1.1 | H15: Kewajiban yang berasal dari simpanan yang diterima
F16: 003 | G16: 1.1.1 | H16: Simpanan stabil dari Nasabah Perorangan | I16: ='Input Bank'!$J16 -> 0.05 | J16: =IF(I16="", K16, I16) -> 0.05 | K16: 0.05 | L16: 0.05 | M16: =MAX(MIN(L16, J16), K16) -> 0.05 | O16: =IF(Dashboard!$M$7="Input LCR bank",J16,M16) -> 0.05 | P16: 1
F17: 004 | G17: 1.1.2 | H17: Simpanan kurang stabil dari Nasabah Perorangan yang dijamin LPS | I17: ='Input Bank'!$J17 -> 0.1 | J17: =IF(I17="", K17, I17) -> 0.1 | K17: 0.1 | L17: 0.1 | M17: =MAX(MIN(L17, J17), K17) -> 0.1 | O17: =IF(Dashboard!$M$7="Input LCR bank",J17,M17) -> 0.1 | P17: 1
F18: 005 | G18: 1.1.3 | H18: Simpanan kurang stabil Nasabah Perorangan yang tidak dijamin LPS | I18: ='Input Bank'!$J18 -> 0.1 | J18: =IF(I18="", K18, I18) -> 0.1 | K18: 0.1 | L18: 0.1 | M18: =MAX(MIN(L18, J18), K18) -> 0.1 | O18: =IF(Dashboard!$M$7="Input LCR bank",J18,M18) -> 0.1 | P18: 1
F19: 006 | G19: 1.1.4 | H19: Pendanaan Stabil dari Nasabah Usaha Mikro dan Usaha Kecil | I19: ='Input Bank'!$J19 -> 0.05 | J19: =IF(I19="", K19, I19) -> 0.05 | K19: 0.05 | L19: 0.05 | M19: =MAX(MIN(L19, J19), K19) -> 0.05 | O19: =IF(Dashboard!$M$7="Input LCR bank",J19,M19) -> 0.05 | P19: 1
F20: 007 | G20: 1.1.5 | H20: Pendanaan kurang Stabil dari Nasabah Usaha Mikro dan Usaha Kecil yang dijamin LPS | I20: ='Input Bank'!$J20 -> 0.1 | J20: =IF(I20="", K20, I20) -> 0.1 | K20: 0.1 | L20: 0.1 | M20: =MAX(MIN(L20, J20), K20) -> 0.1 | O20: =IF(Dashboard!$M$7="Input LCR bank",J20,M20) -> 0.1 | P20: 1
F21: 008 | G21: 1.1.6 | H21: Pendanaan kurang Stabil dari Nasabah Usaha Mikro dan Usaha Kecil yang tidak dijamin LPS | I21: ='Input Bank'!$J21 -> 0.1 | J21: =IF(I21="", K21, I21) -> 0.1 | K21: 0.1 | L21: 0.1 | M21: =MAX(MIN(L21, J21), K21) -> 0.1 | O21: =IF(Dashboard!$M$7="Input LCR bank",J21,M21) -> 0.1 | P21: 1
F22: 009 | G22: 1.1.7 | H22: Simpanan operasional nasabah korporasi yang dijamin LPS | I22: ='Input Bank'!$J22 -> 0.05 | J22: =IF(I22="", K22, I22) -> 0.05 | K22: 0.05 | L22: 0.05 | M22: =MAX(MIN(L22, J22), K22) -> 0.05 | O22: =IF(Dashboard!$M$7="Input LCR bank",J22,M22) -> 0.05 | P22: 1
F23: 010 | G23: 1.1.8 | H23: Simpanan operasional nasabah korporasi yang tidak dijamin LPS | I23: ='Input Bank'!$J23 -> 0.25 | J23: =IF(I23="", K23, I23) -> 0.25 | K23: 0.25 | L23: 0.25 | M23: =MAX(MIN(L23, J23), K23) -> 0.25 | O23: =IF(Dashboard!$M$7="Input LCR bank",J23,M23) -> 0.25 | P23: 1
F24: 011 | G24: 1.1.9 | H24: Penarikan Simpanan Non-Operasional dan/atau kewajiban lainnya yang bersifat non-operasional dari:
F25: 012 | G25: 1.1.10 | H25: Bank | I25: ='Input Bank'!$J25 -> 1 | J25: =IF(I25="", K25, I25) -> 1 | K25: 1 | L25: 1 | M25: 1 | O25: =IF(Dashboard!$M$7="Input LCR bank",J25,M25) -> 1 | P25: 1
F26: 013 | G26: 1.1.11 | H26: LJK lainnya | I26: ='Input Bank'!$J26 -> 1 | J26: =IF(I26="", K26, I26) -> 1 | K26: 1 | L26: 1 | M26: =MAX(MIN(L26, J26), K26) -> 1 | O26: =IF(Dashboard!$M$7="Input LCR bank",J26,M26) -> 1 | P26: 1
F27: 014 | G27: 1.1.12 | H27: Korporasi non-finansial yang dijamin LPS | I27: ='Input Bank'!$J27 -> 0.2 | J27: =IF(I27="", K27, I27) -> 0.2 | K27: 0.2 | L27: 0.2 | M27: =MAX(MIN(L27, J27), K27) -> 0.2 | O27: =IF(Dashboard!$M$7="Input LCR bank",J27,M27) -> 0.2 | P27: 1
F28: 015 | G28: 1.1.13 | H28: Korporasi non-finansial yang tidak dijamin LPS | I28: ='Input Bank'!$J28 -> 0.4 | J28: =IF(I28="", K28, I28) -> 0.4 | K28: 0.4 | L28: 0.4 | M28: =MAX(MIN(L28, J28), K28) -> 0.4 | O28: =IF(Dashboard!$M$7="Input LCR bank",J28,M28) -> 0.4 | P28: 1
F29: 016 | G29: 1.1.14 | H29: Pemerintah pusat, Bank Indonesia, multilateral, dan entitas publik yang dijamin LPS | I29: ='Input Bank'!$J29 -> 0.2 | J29: =IF(I29="", L29, I29) -> 0.2 | K29: 0.2 | L29: 0.2 | M29: =MAX(MIN(L29, J29), K29) -> 0.2 | O29: =IF(Dashboard!$M$7="Input LCR bank",J29,M29) -> 0.2 | P29: 1
F30: 017 | G30: 1.1.15 | H30: Pemerintah pusat, Bank Indonesia, multilateral, dan entitas publik yang tidak dijamin LPS | I30: ='Input Bank'!$J30 -> 0.4 | J30: =IF(I30="", K30, I30) -> 0.4 | K30: 0.4 | L30: 0.4 | M30: =MAX(MIN(L30, J30), K30) -> 0.4 | O30: =IF(Dashboard!$M$7="Input LCR bank",J30,M30) -> 0.4 | P30: 1
F31: 018 | G31: 1.2 | H31: Kewajiban terkait efek yang diterbitkan
F32: 019 | G32: 1.2.1 | H32: Surat berharga berupa surat utang yang diterbitkan Bank tanpa agunan | I32: ='Input Bank'!$J32 -> 1 | J32: =IF(I32="", K32, I32) -> 1 | K32: 1 | L32: 1 | M32: =MAX(MIN(L32, J32), K32) -> 1 | O32: =IF(Dashboard!$M$7="Input LCR bank",J32,M32) -> 1
F33: 020 | G33: 1.2.2 | H33: Lainnya | I33: ='Input Bank'!$J33 -> 1 | J33: =IF(I33="", K33, I33) -> 1 | K33: 1 | L33: 1 | M33: =MAX(MIN(L33, J33), K33) -> 1 | O33: =IF(Dashboard!$M$7="Input LCR bank",J33,M33) -> 1
F34: 021 | G34: 1.3 | H34: Pendanaan dengan agunan (secured funding)
F35: 022 | G35: 1.3.1 | H35: Kewajiban timbul dari secured funding atau transaksi pasar modal dengan pihak lawan selain Bank Indonesia:
F36: 023 | G36: 1.3.2 | H36: Transaksi dilakukan dengan agunan HQLA Level 1 | I36: ='Input Bank'!$J36 -> 0 | J36: 0 | K36: 0 | L36: 1 | M36: =MAX(MIN(L36, J36), K36) -> 0 | O36: =IF(Dashboard!$M$7="Input LCR bank",J36,M36) -> 0
F37: 024 | G37: 1.3.3 | H37: Transaksi dilakukan dengan agunan HQLA Level 2A | I37: ='Input Bank'!$J37 -> 0.15 | J37: 0.15 | K37: 0.15 | L37: 1 | M37: =MAX(MIN(L37, J37), K37) -> 0.15 | O37: =IF(Dashboard!$M$7="Input LCR bank",J37,M37) -> 0.15
F38: 025 | G38: 1.3.4 | H38: Transaksi dilakukan dengan Pemerintah Pusat atau entitas sektor publik yang memiliki bobot risiko paling tinggi 20% atau bank pembangunan multilateral, dengan agunan selain HQLA Level 1 atau HQLA Level 2A | I38: ='Input Bank'!$J38 -> 0.25 | J38: 0.25 | K38: 0.25 | L38: 1 | M38: =MAX(MIN(L38, J38), K38) -> 0.25 | O38: =IF(Dashboard!$M$7="Input LCR bank",J38,M38) -> 0.25
F39: 026 | G39: 1.3.5 | H39: Transaksi dilakukan dengan agunan HQLA Level 2B berupa EBA | I39: ='Input Bank'!$J39 -> 0.25 | J39: 0.25 | K39: 0.25 | L39: 1 | M39: =MAX(MIN(L39, J39), K39) -> 0.25 | O39: =IF(Dashboard!$M$7="Input LCR bank",J39,M39) -> 0.25
F40: 027 | G40: 1.3.6 | H40: Transaksi dilakukan dengan agunan HQLA Level 2B berupa selain EBA | I40: ='Input Bank'!$J40 -> 0.5 | J40: 0.5 | K40: 0.3 | L40: 1 | M40: =MAX(MIN(L40, J40), K40) -> 0.5 | O40: =IF(Dashboard!$M$7="Input LCR bank",J40,M40) -> 0.5
F41: 028 | G41: 1.3.7 | H41: Transaksi dilakukan dengan agunan selain HQLA | I41: ='Input Bank'!$J41 -> 1 | J41: 1 | K41: 1 | L41: 1 | M41: =MAX(MIN(L41, J41), K41) -> 1 | O41: =IF(Dashboard!$M$7="Input LCR bank",J41,M41) -> 1
F42: 029 | G42: 1.3.8 | H42: Kewajiban timbul dari secured funding atau transaksi pasar modal dengan Bank Indonesia sebagai pihak lawan:
F43: 030 | G43: 1.3.9 | H43: Transaksi dilakukan dengan agunan HQLA Level 1 | I43: ='Input Bank'!$J43 -> 0 | J43: 0 | K43: 0 | L43: 0 | M43: 0 | O43: =IF(Dashboard!$M$7="Input LCR bank",J43,M43) -> 0
F44: 031 | G44: 1.3.10 | H44: Transaksi dilakukan dengan agunan HQLA Level 2A | I44: ='Input Bank'!$J44 -> 0 | J44: 0 | K44: 0 | L44: 0 | M44: 0 | O44: =IF(Dashboard!$M$7="Input LCR bank",J44,M44) -> 0
F45: 032 | G45: 1.3.11 | H45: Transaksi dilakukan dengan agunan HQLA Level 2B berupa EBA | I45: ='Input Bank'!$J45 -> 0 | J45: 0 | K45: 0 | L45: 0 | M45: 0 | O45: =IF(Dashboard!$M$7="Input LCR bank",J45,M45) -> 0
F46: 033 | G46: 1.3.12 | H46: Transaksi dilakukan dengan agunan HQLA Level 2B berupa selain EBA | I46: ='Input Bank'!$J46 -> 0 | J46: 0 | K46: 0 | L46: 0 | M46: 0 | O46: =IF(Dashboard!$M$7="Input LCR bank",J46,M46) -> 0
F47: 034 | G47: 1.3.13 | H47: Transaksi dilakukan dengan agunan selain HQLA | I47: ='Input Bank'!$J47 -> 0 | J47: 0 | K47: 0 | L47: 0 | M47: 0 | O47: =IF(Dashboard!$M$7="Input LCR bank",J47,M47) -> 0
F48: 035 | G48: 1.4 | H48: FX-swaps jatuh tempo | I48: ='Input Bank'!$J48 -> 1 | J48: =IF(I48="", K48, I48) -> 1 | K48: 1 | L48: 1 | M48: =MAX(MIN(L48, J48), K48) -> 1 | O48: =IF(Dashboard!$M$7="Input LCR bank",J48,M48) -> 1 | P48: 1
F49: 036 | G49: 1.5 | H49: Arus kas keluar lainnya terkait transaksi derivatif selain 1.4 | I49: ='Input Bank'!$J49 -> 1 | J49: =IF(I49="", L49, I49) -> 1 | K49: 0 | L49: 1 | M49: =MAX(MIN(L49, J49), K49) -> 1 | O49: =IF(Dashboard!$M$7="Input LCR bank",J49,M49) -> 1 | P49: 1
...

Sheet SPM Skenario Dasar
H9: LCR (30 hari) & Benchmark (90 hari)
K11: =TEXT(K12,"ddd") -> MM/DD/YYYY
K12: ='Header & Notes'!J10 -> MM/DD/YYYY | AQ12: =#REF!+7 -> #REF! | AR12: =AQ12+ROUNDDOWN(21/2,0) -> #REF! | AS12: =AR12+30/2 -> #REF! | AT12: =AS12+30/2 -> #REF! | AU12: =AT12+30/2 -> #REF! | AV12: =AU12+30/2 -> #REF! | AW12: =AV12+92/2 -> #REF! | AX12: =AW12+92/2 -> #REF! | AY12: =AX12+ROUNDDOWN(365/2,0) -> #REF! | AZ12: =AY12+ROUNDDOWN(3*365/2,) -> #REF! | BA12: =AZ12+3650/2 -> #REF!
F13: Kode | G13: Baris | H13: Item | I13: Weight - open | J13: Weight - term | K13: Stok awal | L13: Tanpa Maturitas (Open) | M13: O/N (selain Open) | N13: Hari-2 | O13: Hari-3 | P13: Hari-4 | Q13: Hari-5 | R13: Hari-6 | S13: Hari-7 | T13: Hari-8 | U13: Hari-9 | V13: Hari-10 | W13: Hari-11 | X13: Hari-12 | Y13: Hari-13 | Z13: Hari-14 | AA13: Hari-15 | AB13: Hari-16 | AC13: Hari-17 | AD13: Hari-18 | AE13: Hari-19 | AF13: Hari-20 | AG13: Hari-21 | AH13: Hari-22 | AI13: Hari-23 | AJ13: Hari-24 | AK13: Hari-25 | AL13: Hari-26 | AM13: Hari-27 | AN13: Hari-28 | AO13: Hari-29 | AP13: Hari-30 | AQ13: > mg 4 s.d. mg 5 | AR13: > mg 5 s.d. 2 bln | AS13: > 2 bln s.d 3 bln | AT13: > 3 bln s.d 4 bln | AU13: > 4 bln s.d 5 bln | AV13: > 5 bln s.d 6 bln | AW13: > 6 bln s.d. 9 bln | AX13: > 9 bln s.d. 12 bln | AY13: > 12 bln s.d. 2 thn | AZ13: > 2 thn s.d. 5 thn | BA13: > 5 thn
F14: 001 | G14: 1 | H14: ARUS KAS KELUAR
A15: =Bobot!#REF! -> #REF! | F15: 002 | G15: 1.1 | H15: Kewajiban yang berasal dari simpanan yang diterima | L15: =SUM(L16:L30) -> 0 | M15: =SUM(M16:M30) -> 0 | N15: =SUM(N16:N30) -> 0 | O15: =SUM(O16:O30) -> 0 | P15: =SUM(P16:P30) -> 0 | Q15: =SUM(Q16:Q30) -> 0 | R15: =SUM(R16:R30) -> 0 | S15: =SUM(S16:S30) -> 0 | ... BA15: =SUM(BA16:BA30) -> 0
A16: =Bobot!#REF! -> #REF! | F16: 003 | G16: 1.1.1 | H16: Simpanan stabil dari Nasabah Perorangan | I16: =Bobot!O16 -> 0.05 | J16: =Bobot!O16 -> 0.05 | L16: =IF(Bobot!$P16=0,1,0)*('Input Bank'!L16+'Input Bank'!K16)*I16 -> 0 | M16: =Bobot!$P16*($I16*('Input Bank'!$K16+'Input Bank'!$L16)/30)+($J16*'Input Bank'!M16) -> 0 | N16: =Bobot!$P16*($I16*('Input Bank'!$K16+'Input Bank'!$L16)/30)+($J16*'Input Bank'!N16) -> 0 | O16: =Bobot!$P16*($I16*('Input Bank'!$K16+'Input Bank'!$L16)/30)+($J16*'Input Bank'!O16) -> 0 | P16: =Bobot!$P16*($I16*('Input Bank'!$K16+'Input Bank'!$L16)/30)+($J16*'Input Bank'!P16) -> 0 | Q16: =Bobot!$P16*($I16*('Input Bank'!$K16+'Input Bank'!$L16)/30)+($J16*'Input Bank'!Q16) -> 0 | R16: =Bobot!$P16*($I16*('Input Bank'!$K16+'Input Bank'!$L16)/30)+($J16*'Input Bank'!R16) -> 0 | S16: =Bobot!$P16*($I16*('Input Bank'!$K16+'Input Bank'!$L16)/30)+($J16*'Input Bank'!S16) -> 0 | T16: =Bobot!$P16*($I16*('Input Bank'!$K16+'Input Bank'!$L16)/30)+($J16*'Input Bank'!T16) -> 0 | ... AP16: =Bobot!$P16*($I16*('Input Bank'!$K16+'Input Bank'!$L16)/30)+($J16*'Input Bank'!AP16) -> 0 | AQ16: =$J16*'Input Bank'!AQ16 -> 0 | AR16: =$J16*'Input Bank'!AR16 -> 0 | AS16: =$J16*'Input Bank'!AS16 -> 0 | AT16: =$J16*'Input Bank'!AT16 -> 0 | AU16: =$J16*'Input Bank'!AU16 -> 0 | AV16: =$J16*'Input Bank'!AV16 -> 0 | AW16: =$J16*'Input Bank'!AW16 -> 0 | AX16: =$J16*'Input Bank'!AX16 -> 0 | ... BA16: =$J16*'Input Bank'!BA16 -> 0
A17: =Bobot!#REF! -> #REF! | F17: 004 | G17: 1.1.2 | H17: Simpanan kurang stabil dari Nasabah Perorangan yang dijamin LPS | I17: =Bobot!O17 -> 0.1 | J17: =Bobot!O17 -> 0.1 | L17: =IF(Bobot!$P17=0,1,0)*('Input Bank'!L17+'Input Bank'!K17)*I17 -> 0 | M17: =Bobot!$P17*($I17*('Input Bank'!$K17+'Input Bank'!$L17)/30)+($J17*'Input Bank'!M17) -> 0 | N17: =Bobot!$P17*($I17*('Input Bank'!$K17+'Input Bank'!$L17)/30)+($J17*'Input Bank'!N17) -> 0 | O17: =Bobot!$P17*($I17*('Input Bank'!$K17+'Input Bank'!$L17)/30)+($J17*'Input Bank'!O17) -> 0 | P17: =Bobot!$P17*($I17*('Input Bank'!$K17+'Input Bank'!$L17)/30)+($J17*'Input Bank'!P17) -> 0 | Q17: =Bobot!$P17*($I17*('Input Bank'!$K17+'Input Bank'!$L17)/30)+($J17*'Input Bank'!Q17) -> 0 | R17: =Bobot!$P17*($I17*('Input Bank'!$K17+'Input Bank'!$L17)/30)+($J17*'Input Bank'!R17) -> 0 | S17: =Bobot!$P17*($I17*('Input Bank'!$K17+'Input Bank'!$L17)/30)+($J17*'Input Bank'!S17) -> 0 | T17: =Bobot!$P17*($I17*('Input Bank'!$K17+'Input Bank'!$L17)/30)+($J17*'Input Bank'!T17) -> 0 | ... AP17: =Bobot!$P17*($I17*('Input Bank'!$K17+'Input Bank'!$L17)/30)+($J17*'Input Bank'!AP17) -> 0 | AQ17: =$J17*'Input Bank'!AQ17 -> 0 | AR17: =$J17*'Input Bank'!AR17 -> 0 | AS17: =$J17*'Input Bank'!AS17 -> 0 | AT17: =$J17*'Input Bank'!AT17 -> 0 | AU17: =$J17*'Input Bank'!AU17 -> 0 | AV17: =$J17*'Input Bank'!AV17 -> 0 | AW17: =$J17*'Input Bank'!AW17 -> 0 | AX17: =$J17*'Input Bank'!AX17 -> 0 | ... BA17: =$J17*'Input Bank'!BA17 -> 0
A18: =Bobot!#REF! -> #REF! | F18: 005 | G18: 1.1.3 | H18: Simpanan kurang stabil Nasabah Perorangan yang tidak dijamin LPS | I18: =Bobot!O18 -> 0.1 | J18: =Bobot!O18 -> 0.1 | L18: =IF(Bobot!$P18=0,1,0)*('Input Bank'!L18+'Input Bank'!K18)*I18 -> 0 | M18: =Bobot!$P18*($I18*('Input Bank'!$K18+'Input Bank'!$L18)/30)+($J18*'Input Bank'!M18) -> 0 | N18: =Bobot!$P18*($I18*('Input Bank'!$K18+'Input Bank'!$L18)/30)+($J18*'Input Bank'!N18) -> 0 | O18: =Bobot!$P18*($I18*('Input Bank'!$K18+'Input Bank'!$L18)/30)+($J18*'Input Bank'!O18) -> 0 | P18: =Bobot!$P18*($I18*('Input Bank'!$K18+'Input Bank'!$L18)/30)+($J18*'Input Bank'!P18) -> 0 | Q18: =Bobot!$P18*($I18*('Input Bank'!$K18+'Input Bank'!$L18)/30)+($J18*'Input Bank'!Q18) -> 0 | R18: =Bobot!$P18*($I18*('Input Bank'!$K18+'Input Bank'!$L18)/30)+($J18*'Input Bank'!R18) -> 0 | S18: =Bobot!$P18*($I18*('Input Bank'!$K18+'Input Bank'!$L18)/30)+($J18*'Input Bank'!S18) -> 0 | T18: =Bobot!$P18*($I18*('Input Bank'!$K18+'Input Bank'!$L18)/30)+($J18*'Input Bank'!T18) -> 0 | ... AP18: =Bobot!$P18*($I18*('Input Bank'!$K18+'Input Bank'!$L18)/30)+($J18*'Input Bank'!AP18) -> 0 | AQ18: =$J18*'Input Bank'!AQ18 -> 0 | AR18: =$J18*'Input Bank'!AR18 -> 0 | AS18: =$J18*'Input Bank'!AS18 -> 0 | AT18: =$J18*'Input Bank'!AT18 -> 0 | AU18: =$J18*'Input Bank'!AU18 -> 0 | AV18: =$J18*'Input Bank'!AV18 -> 0 | AW18: =$J18*'Input Bank'!AW18 -> 0 | AX18: =$J18*'Input Bank'!AX18 -> 0 | ... BA18: =$J18*'Input Bank'!BA18 -> 0
F19: 006 | G19: 1.1.4 | H19: Pendanaan Stabil dari Nasabah Usaha Mikro dan Usaha Kecil | I19: =Bobot!O19 -> 0.05 | J19: =Bobot!O19 -> 0.05 | L19: =IF(Bobot!$P19=0,1,0)*('Input Bank'!L19+'Input Bank'!K19)*I19 -> 0 | M19: =Bobot!$P19*($I19*('Input Bank'!$K19+'Input Bank'!$L19)/30)+($J19*'Input Bank'!M19) -> 0 | N19: =Bobot!$P19*($I19*('Input Bank'!$K19+'Input Bank'!$L19)/30)+($J19*'Input Bank'!N19) -> 0 | O19: =Bobot!$P19*($I19*('Input Bank'!$K19+'Input Bank'!$L19)/30)+($J19*'Input Bank'!O19) -> 0 | P19: =Bobot!$P19*($I19*('Input Bank'!$K19+'Input Bank'!$L19)/30)+($J19*'Input Bank'!P19) -> 0 | Q19: =Bobot!$P19*($I19*('Input Bank'!$K19+'Input Bank'!$L19)/30)+($J19*'Input Bank'!Q19) -> 0 | R19: =Bobot!$P19*($I19*('Input Bank'!$K19+'Input Bank'!$L19)/30)+($J19*'Input Bank'!R19) -> 0 | S19: =Bobot!$P19*($I19*('Input Bank'!$K19+'Input Bank'!$L19)/30)+($J19*'Input Bank'!S19) -> 0 | T19: =Bobot!$P19*($I19*('Input Bank'!$K19+'Input Bank'!$L19)/30)+($J19*'Input Bank'!T19) -> 0 | ... AP19: =Bobot!$P19*($I19*('Input Bank'!$K19+'Input Bank'!$L19)/30)+($J19*'Input Bank'!AP19) -> 0 | AQ19: =$J19*'Input Bank'!AQ19 -> 0 | AR19: =$J19*'Input Bank'!AR19 -> 0 | AS19: =$J19*'Input Bank'!AS19 -> 0 | AT19: =$J19*'Input Bank'!AT19 -> 0 | AU19: =$J19*'Input Bank'!AU19 -> 0 | AV19: =$J19*'Input Bank'!AV19 -> 0 | AW19: =$J19*'Input Bank'!AW19 -> 0 | AX19: =$J19*'Input Bank'!AX19 -> 0 | ... BA19: =$J19*'Input Bank'!BA19 -> 0
A20: =Bobot!P37 -> 0 | F20: 007 | G20: 1.1.5 | H20: Pendanaan kurang Stabil dari Nasabah Usaha Mikro dan Usaha Kecil yang dijamin LPS | I20: =Bobot!O20 -> 0.1 | J20: =Bobot!O20 -> 0.1 | L20: =IF(Bobot!$P20=0,1,0)*('Input Bank'!L20+'Input Bank'!K20)*I20 -> 0 | M20: =Bobot!$P20*($I20*('Input Bank'!$K20+'Input Bank'!$L20)/30)+($J20*'Input Bank'!M20) -> 0 | N20: =Bobot!$P20*($I20*('Input Bank'!$K20+'Input Bank'!$L20)/30)+($J20*'Input Bank'!N20) -> 0 | O20: =Bobot!$P20*($I20*('Input Bank'!$K20+'Input Bank'!$L20)/30)+($J20*'Input Bank'!O20) -> 0 | P20: =Bobot!$P20*($I20*('Input Bank'!$K20+'Input Bank'!$L20)/30)+($J20*'Input Bank'!P20) -> 0 | Q20: =Bobot!$P20*($I20*('Input Bank'!$K20+'Input Bank'!$L20)/30)+($J20*'Input Bank'!Q20) -> 0 | R20: =Bobot!$P20*($I20*('Input Bank'!$K20+'Input Bank'!$L20)/30)+($J20*'Input Bank'!R20) -> 0 | S20: =Bobot!$P20*($I20*('Input Bank'!$K20+'Input Bank'!$L20)/30)+($J20*'Input Bank'!S20) -> 0 | T20: =Bobot!$P20*($I20*('Input Bank'!$K20+'Input Bank'!$L20)/30)+($J20*'Input Bank'!T20) -> 0 | ... AP20: =Bobot!$P20*($I20*('Input Bank'!$K20+'Input Bank'!$L20)/30)+($J20*'Input Bank'!AP20) -> 0 | AQ20: =$J20*'Input Bank'!AQ20 -> 0 | AR20: =$J20*'Input Bank'!AR20 -> 0 | AS20: =$J20*'Input Bank'!AS20 -> 0 | AT20: =$J20*'Input Bank'!AT20 -> 0 | AU20: =$J20*'Input Bank'!AU20 -> 0 | AV20: =$J20*'Input Bank'!AV20 -> 0 | AW20: =$J20*'Input Bank'!AW20 -> 0 | AX20: =$J20*'Input Bank'!AX20 -> 0 | ... BA20: =$J20*'Input Bank'!BA20 -> 0
A21: =Bobot!#REF! -> #REF! | F21: 008 | G21: 1.1.6 | H21: Pendanaan kurang Stabil dari Nasabah Usaha Mikro dan Usaha Kecil yang tidak dijamin LPS | I21: =Bobot!O21 -> 0.1 | J21: =Bobot!O21 -> 0.1 | L21: =IF(Bobot!$P21=0,1,0)*('Input Bank'!L21+'Input Bank'!K21)*I21 -> 0 | M21: =Bobot!$P21*($I21*('Input Bank'!$K21+'Input Bank'!$L21)/30)+($J21*'Input Bank'!M21) -> 0 | N21: =Bobot!$P21*($I21*('Input Bank'!$K21+'Input Bank'!$L21)/30)+($J21*'Input Bank'!N21) -> 0 | O21: =Bobot!$P21*($I21*('Input Bank'!$K21+'Input Bank'!$L21)/30)+($J21*'Input Bank'!O21) -> 0 | P21: =Bobot!$P21*($I21*('Input Bank'!$K21+'Input Bank'!$L21)/30)+($J21*'Input Bank'!P21) -> 0 | Q21: =Bobot!$P21*($I21*('Input Bank'!$K21+'Input Bank'!$L21)/30)+($J21*'Input Bank'!Q21) -> 0 | R21: =Bobot!$P21*($I21*('Input Bank'!$K21+'Input Bank'!$L21)/30)+($J21*'Input Bank'!R21) -> 0 | S21: =Bobot!$P21*($I21*('Input Bank'!$K21+'Input Bank'!$L21)/30)+($J21*'Input Bank'!S21) -> 0 | T21: =Bobot!$P21*($I21*('Input Bank'!$K21+'Input Bank'!$L21)/30)+($J21*'Input Bank'!T21) -> 0 | ... AP21: =Bobot!$P21*($I21*('Input Bank'!$K21+'Input Bank'!$L21)/30)+($J21*'Input Bank'!AP21) -> 0 | AQ21: =$J21*'Input Bank'!AQ21 -> 0 | AR21: =$J21*'Input Bank'!AR21 -> 0 | AS21: =$J21*'Input Bank'!AS21 -> 0 | AT21: =$J21*'Input Bank'!AT21 -> 0 | AU21: =$J21*'Input Bank'!AU21 -> 0 | AV21: =$J21*'Input Bank'!AV21 -> 0 | AW21: =$J21*'Input Bank'!AW21 -> 0 | AX21: =$J21*'Input Bank'!AX21 -> 0 | ... BA21: =$J21*'Input Bank'!BA21 -> 0
A22: =Bobot!#REF! -> #REF! | F22: 009 | G22: 1.1.7 | H22: Simpanan operasional nasabah korporasi yang dijamin LPS | I22: =Bobot!O22 -> 0.05 | J22: =Bobot!O22 -> 0.05 | L22: =IF(Bobot!$P22=0,1,0)*('Input Bank'!L22+'Input Bank'!K22)*I22 -> 0 | M22: =Bobot!$P22*($I22*('Input Bank'!$K22+'Input Bank'!$L22)/30)+($J22*'Input Bank'!M22) -> 0 | N22: =Bobot!$P22*($I22*('Input Bank'!$K22+'Input Bank'!$L22)/30)+($J22*'Input Bank'!N22) -> 0 | O22: =Bobot!$P22*($I22*('Input Bank'!$K22+'Input Bank'!$L22)/30)+($J22*'Input Bank'!O22) -> 0 | P22: =Bobot!$P22*($I22*('Input Bank'!$K22+'Input Bank'!$L22)/30)+($J22*'Input Bank'!P22) -> 0 | Q22: =Bobot!$P22*($I22*('Input Bank'!$K22+'Input Bank'!$L22)/30)+($J22*'Input Bank'!Q22) -> 0 | R22: =Bobot!$P22*($I22*('Input Bank'!$K22+'Input Bank'!$L22)/30)+($J22*'Input Bank'!R22) -> 0 | S22: =Bobot!$P22*($I22*('Input Bank'!$K22+'Input Bank'!$L22)/30)+($J22*'Input Bank'!S22) -> 0 | T22: =Bobot!$P22*($I22*('Input Bank'!$K22+'Input Bank'!$L22)/30)+($J22*'Input Bank'!T22) -> 0 | ... AP22: =Bobot!$P22*($I22*('Input Bank'!$K22+'Input Bank'!$L22)/30)+($J22*'Input Bank'!AP22) -> 0 | AQ22: =$J22*'Input Bank'!AQ22 -> 0 | AR22: =$J22*'Input Bank'!AR22 -> 0 | AS22: =$J22*'Input Bank'!AS22 -> 0 | AT22: =$J22*'Input Bank'!AT22 -> 0 | AU22: =$J22*'Input Bank'!AU22 -> 0 | AV22: =$J22*'Input Bank'!AV22 -> 0 | AW22: =$J22*'Input Bank'!AW22 -> 0 | AX22: =$J22*'Input Bank'!AX22 -> 0 | ... BA22: =$J22*'Input Bank'!BA22 -> 0
A23: =Bobot!P39 -> 0 | F23: 010 | G23: 1.1.8 | H23: Simpanan operasional nasabah korporasi yang tidak dijamin LPS | I23: =Bobot!O23 -> 0.25 | J23: =Bobot!O23 -> 0.25 | L23: =IF(Bobot!$P23=0,1,0)*('Input Bank'!L23+'Input Bank'!K23)*I23 -> 0 | M23: =Bobot!$P23*($I23*('Input Bank'!$K23+'Input Bank'!$L23)/30)+($J23*'Input Bank'!M23) -> 0 | N23: =Bobot!$P23*($I23*('Input Bank'!$K23+'Input Bank'!$L23)/30)+($J23*'Input Bank'!N23) -> 0 | O23: =Bobot!$P23*($I23*('Input Bank'!$K23+'Input Bank'!$L23)/30)+($J23*'Input Bank'!O23) -> 0 | P23: =Bobot!$P23*($I23*('Input Bank'!$K23+'Input Bank'!$L23)/30)+($J23*'Input Bank'!P23) -> 0 | Q23: =Bobot!$P23*($I23*('Input Bank'!$K23+'Input Bank'!$L23)/30)+($J23*'Input Bank'!Q23) -> 0 | R23: =Bobot!$P23*($I23*('Input Bank'!$K23+'Input Bank'!$L23)/30)+($J23*'Input Bank'!R23) -> 0 | S23: =Bobot!$P23*($I23*('Input Bank'!$K23+'Input Bank'!$L23)/30)+($J23*'Input Bank'!S23) -> 0 | T23: =Bobot!$P23*($I23*('Input Bank'!$K23+'Input Bank'!$L23)/30)+($J23*'Input Bank'!T23) -> 0 | ... AP23: =Bobot!$P23*($I23*('Input Bank'!$K23+'Input Bank'!$L23)/30)+($J23*'Input Bank'!AP23) -> 0 | AQ23: =$J23*'Input Bank'!AQ23 -> 0 | AR23: =$J23*'Input Bank'!AR23 -> 0 | AS23: =$J23*'Input Bank'!AS23 -> 0 | AT23: =$J23*'Input Bank'!AT23 -> 0 | AU23: =$J23*'Input Bank'!AU23 -> 0 | AV23: =$J23*'Input Bank'!AV23 -> 0 | AW23: =$J23*'Input Bank'!AW23 -> 0 | AX23: =$J23*'Input Bank'!AX23 -> 0 | ... BA23: =$J23*'Input Bank'!BA23 -> 0
A24: =Bobot!#REF! -> #REF! | F24: 011 | G24: 1.1.9 | H24: Penarikan Simpanan Non-Operasional dan/atau kewajiban lainnya yang bersifat non-operasional dari: | I24: =Bobot!O24 -> 0 | J24: =Bobot!O24 -> 0
A25: =Bobot!#REF! -> #REF! | F25: 012 | G25: 1.1.10 | H25: Bank | I25: =Bobot!O25 -> 1 | J25: =Bobot!O25 -> 1 | L25: =IF(Bobot!$P25=0,1,0)*('Input Bank'!L26+'Input Bank'!K25)*I25 -> 0 | M25: =Bobot!$P25*($I25*('Input Bank'!$K25+'Input Bank'!$L25)/30)+($J25*'Input Bank'!M25) -> 0 | N25: =Bobot!$P25*($I25*('Input Bank'!$K25+'Input Bank'!$L25)/30)+($J25*'Input Bank'!N25) -> 0 | O25: =Bobot!$P25*($I25*('Input Bank'!$K25+'Input Bank'!$L25)/30)+($J25*'Input Bank'!O25) -> 0 | P25: =Bobot!$P25*($I25*('Input Bank'!$K25+'Input Bank'!$L25)/30)+($J25*'Input Bank'!P25) -> 0 | Q25: =Bobot!$P25*($I25*('Input Bank'!$K25+'Input Bank'!$L25)/30)+($J25*'Input Bank'!Q25) -> 0 | R25: =Bobot!$P25*($I25*('Input Bank'!$K25+'Input Bank'!$L25)/30)+($J25*'Input Bank'!R25) -> 0 | S25: =Bobot!$P25*($I25*('Input Bank'!$K25+'Input Bank'!$L25)/30)+($J25*'Input Bank'!S25) -> 0 | T25: =Bobot!$P25*($I25*('Input Bank'!$K25+'Input Bank'!$L25)/30)+($J25*'Input Bank'!T25) -> 0 | ... AP25: =Bobot!$P25*($I25*('Input Bank'!$K25+'Input Bank'!$L25)/30)+($J25*'Input Bank'!AP25) -> 0 | AQ25: =$J25*'Input Bank'!AQ25 -> 0 | AR25: =$J25*'Input Bank'!AR25 -> 0 | AS25: =$J25*'Input Bank'!AS25 -> 0 | AT25: =$J25*'Input Bank'!AT25 -> 0 | AU25: =$J25*'Input Bank'!AU25 -> 0 | AV25: =$J25*'Input Bank'!AV25 -> 0 | AW25: =$J25*'Input Bank'!AW25 -> 0 | AX25: =$J25*'Input Bank'!AX25 -> 0 | ... BA25: =$J25*'Input Bank'!BA25 -> 0
A26: =Bobot!#REF! -> #REF! | F26: 013 | G26: 1.1.11 | H26: LJK lainnya | I26: =Bobot!O26 -> 1 | J26: =Bobot!O26 -> 1 | L26: =IF(Bobot!$P26=0,1,0)*('Input Bank'!L26+'Input Bank'!K26)*I26 -> 0 | M26: =Bobot!$P26*($I26*('Input Bank'!$K26+'Input Bank'!$L26)/30)+($J26*'Input Bank'!M26) -> 0 | N26: =Bobot!$P26*($I26*('Input Bank'!$K26+'Input Bank'!$L26)/30)+($J26*'Input Bank'!N26) -> 0 | O26: =Bobot!$P26*($I26*('Input Bank'!$K26+'Input Bank'!$L26)/30)+($J26*'Input Bank'!O26) -> 0 | P26: =Bobot!$P26*($I26*('Input Bank'!$K26+'Input Bank'!$L26)/30)+($J26*'Input Bank'!P26) -> 0 | Q26: =Bobot!$P26*($I26*('Input Bank'!$K26+'Input Bank'!$L26)/30)+($J26*'Input Bank'!Q26) -> 0 | R26: =Bobot!$P26*($I26*('Input Bank'!$K26+'Input Bank'!$L26)/30)+($J26*'Input Bank'!R26) -> 0 | S26: =Bobot!$P26*($I26*('Input Bank'!$K26+'Input Bank'!$L26)/30)+($J26*'Input Bank'!S26) -> 0 | T26: =Bobot!$P26*($I26*('Input Bank'!$K26+'Input Bank'!$L26)/30)+($J26*'Input Bank'!T26) -> 0 | ... AP26: =Bobot!$P26*($I26*('Input Bank'!$K26+'Input Bank'!$L26)/30)+($J26*'Input Bank'!AP26) -> 0 | AQ26: =$J26*'Input Bank'!AQ26 -> 0 | AR26: =$J26*'Input Bank'!AR26 -> 0 | AS26: =$J26*'Input Bank'!AS26 -> 0 | AT26: =$J26*'Input Bank'!AT26 -> 0 | AU26: =$J26*'Input Bank'!AU26 -> 0 | AV26: =$J26*'Input Bank'!AV26 -> 0 | AW26: =$J26*'Input Bank'!AW26 -> 0 | AX26: =$J26*'Input Bank'!AX26 -> 0 | ... BA26: =$J26*'Input Bank'!BA26 -> 0
A27: =Bobot!#REF! -> #REF! | F27: 014 | G27: 1.1.12 | H27: Korporasi non-finansial yang dijamin LPS | I27: =Bobot!O27 -> 0.2 | J27: =Bobot!O27 -> 0.2 | L27: =IF(Bobot!$P27=0,1,0)*('Input Bank'!L27+'Input Bank'!K27)*I27 -> 0 | M27: =Bobot!$P27*($I27*('Input Bank'!$K27+'Input Bank'!$L27)/30)+($J27*'Input Bank'!M27) -> 0 | N27: =Bobot!$P27*($I27*('Input Bank'!$K27+'Input Bank'!$L27)/30)+($J27*'Input Bank'!N27) -> 0 | O27: =Bobot!$P27*($I27*('Input Bank'!$K27+'Input Bank'!$L27)/30)+($J27*'Input Bank'!O27) -> 0 | P27: =Bobot!$P27*($I27*('Input Bank'!$K27+'Input Bank'!$L27)/30)+($J27*'Input Bank'!P27) -> 0 | Q27: =Bobot!$P27*($I27*('Input Bank'!$K27+'Input Bank'!$L27)/30)+($J27*'Input Bank'!Q27) -> 0 | R27: =Bobot!$P27*($I27*('Input Bank'!$K27+'Input Bank'!$L27)/30)+($J27*'Input Bank'!R27) -> 0 | S27: =Bobot!$P27*($I27*('Input Bank'!$K27+'Input Bank'!$L27)/30)+($J27*'Input Bank'!S27) -> 0 | T27: =Bobot!$P27*($I27*('Input Bank'!$K27+'Input Bank'!$L27)/30)+($J27*'Input Bank'!T27) -> 0 | ... AP27: =Bobot!$P27*($I27*('Input Bank'!$K27+'Input Bank'!$L27)/30)+($J27*'Input Bank'!AP27) -> 0 | AQ27: =$J27*'Input Bank'!AQ27 -> 0 | AR27: =$J27*'Input Bank'!AR27 -> 0 | AS27: =$J27*'Input Bank'!AS27 -> 0 | AT27: =$J27*'Input Bank'!AT27 -> 0 | AU27: =$J27*'Input Bank'!AU27 -> 0 | AV27: =$J27*'Input Bank'!AV27 -> 0 | AW27: =$J27*'Input Bank'!AW27 -> 0 | AX27: =$J27*'Input Bank'!AX27 -> 0 | ... BA27: =$J27*'Input Bank'!BA27 -> 0
A28: =Bobot!#REF! -> #REF! | F28: 015 | G28: 1.1.13 | H28: Korporasi non-finansial yang tidak dijamin LPS | I28: =Bobot!O28 -> 0.4 | J28: =Bobot!O28 -> 0.4 | L28: =IF(Bobot!$P28=0,1,0)*('Input Bank'!L28+'Input Bank'!K28)*I28 -> 0 | M28: =Bobot!$P28*($I28*('Input Bank'!$K28+'Input Bank'!$L28)/30)+($J28*'Input Bank'!M28) -> 0 | N28: =Bobot!$P28*($I28*('Input Bank'!$K28+'Input Bank'!$L28)/30)+($J28*'Input Bank'!N28) -> 0 | O28: =Bobot!$P28*($I28*('Input Bank'!$K28+'Input Bank'!$L28)/30)+($J28*'Input Bank'!O28) -> 0 | P28: =Bobot!$P28*($I28*('Input Bank'!$K28+'Input Bank'!$L28)/30)+($J28*'Input Bank'!P28) -> 0 | Q28: =Bobot!$P28*($I28*('Input Bank'!$K28+'Input Bank'!$L28)/30)+($J28*'Input Bank'!Q28) -> 0 | R28: =Bobot!$P28*($I28*('Input Bank'!$K28+'Input Bank'!$L28)/30)+($J28*'Input Bank'!R28) -> 0 | S28: =Bobot!$P28*($I28*('Input Bank'!$K28+'Input Bank'!$L28)/30)+($J28*'Input Bank'!S28) -> 0 | T28: =Bobot!$P28*($I28*('Input Bank'!$K28+'Input Bank'!$L28)/30)+($J28*'Input Bank'!T28) -> 0 | ... AP28: =Bobot!$P28*($I28*('Input Bank'!$K28+'Input Bank'!$L28)/30)+($J28*'Input Bank'!AP28) -> 0 | AQ28: =$J28*'Input Bank'!AQ28 -> 0 | AR28: =$J28*'Input Bank'!AR28 -> 0 | AS28: =$J28*'Input Bank'!AS28 -> 0 | AT28: =$J28*'Input Bank'!AT28 -> 0 | AU28: =$J28*'Input Bank'!AU28 -> 0 | AV28: =$J28*'Input Bank'!AV28 -> 0 | AW28: =$J28*'Input Bank'!AW28 -> 0 | AX28: =$J28*'Input Bank'!AX28 -> 0 | ... BA28: =$J28*'Input Bank'!BA28 -> 0
A29: =Bobot!#REF! -> #REF! | F29: 016 | G29: 1.1.14 | H29: Pemerintah pusat, Bank Indonesia, multilateral dan entitas publik yang dijamin LPS | I29: =Bobot!O29 -> 0.2 | J29: =Bobot!O29 -> 0.2 | L29: =IF(Bobot!$P29=0,1,0)*('Input Bank'!L29+'Input Bank'!K29)*I29 -> 0 | M29: =Bobot!$P29*($I29*('Input Bank'!$K29+'Input Bank'!$L29)/30)+($J29*'Input Bank'!M29) -> 0 | N29: =Bobot!$P29*($I29*('Input Bank'!$K29+'Input Bank'!$L29)/30)+($J29*'Input Bank'!N29) -> 0 | O29: =Bobot!$P29*($I29*('Input Bank'!$K29+'Input Bank'!$L29)/30)+($J29*'Input Bank'!O29) -> 0 | P29: =Bobot!$P29*($I29*('Input Bank'!$K29+'Input Bank'!$L29)/30)+($J29*'Input Bank'!P29) -> 0 | Q29: =Bobot!$P29*($I29*('Input Bank'!$K29+'Input Bank'!$L29)/30)+($J29*'Input Bank'!Q29) -> 0 | R29: =Bobot!$P29*($I29*('Input Bank'!$K29+'Input Bank'!$L29)/30)+($J29*'Input Bank'!R29) -> 0 | S29: =Bobot!$P29*($I29*('Input Bank'!$K29+'Input Bank'!$L29)/30)+($J29*'Input Bank'!S29) -> 0 | T29: =Bobot!$P29*($I29*('Input Bank'!$K29+'Input Bank'!$L29)/30)+($J29*'Input Bank'!T29) -> 0 | ... AP29: =Bobot!$P29*($I29*('Input Bank'!$K29+'Input Bank'!$L29)/30)+($J29*'Input Bank'!AP29) -> 0 | AQ29: =$J29*'Input Bank'!AQ29 -> 0 | AR29: =$J29*'Input Bank'!AR29 -> 0 | AS29: =$J29*'Input Bank'!AS29 -> 0 | AT29: =$J29*'Input Bank'!AT29 -> 0 | AU29: =$J29*'Input Bank'!AU29 -> 0 | AV29: =$J29*'Input Bank'!AV29 -> 0 | AW29: =$J29*'Input Bank'!AW29 -> 0 | AX29: =$J29*'Input Bank'!AX29 -> 0 | ... BA29: =$J29*'Input Bank'!BA29 -> 0
A30: =Bobot!#REF! -> #REF! | F30: 017 | G30: 1.1.15 | H30: Pemerintah pusat, Bank Indonesia, multilateral dan entitas publik yang tidak dijamin LPS | I30: =Bobot!O30 -> 0.4 | J30: =Bobot!O30 -> 0.4 | L30: =IF(Bobot!$P30=0,1,0)*('Input Bank'!L30+'Input Bank'!K30)*I30 -> 0 | M30: =Bobot!$P30*($I30*('Input Bank'!$K30+'Input Bank'!$L30)/30)+($J30*'Input Bank'!M30) -> 0 | N30: =Bobot!$P30*($I30*('Input Bank'!$K30+'Input Bank'!$L30)/30)+($J30*'Input Bank'!N30) -> 0 | O30: =Bobot!$P30*($I30*('Input Bank'!$K30+'Input Bank'!$L30)/30)+($J30*'Input Bank'!O30) -> 0 | P30: =Bobot!$P30*($I30*('Input Bank'!$K30+'Input Bank'!$L30)/30)+($J30*'Input Bank'!P30) -> 0 | Q30: =Bobot!$P30*($I30*('Input Bank'!$K30+'Input Bank'!$L30)/30)+($J30*'Input Bank'!Q30) -> 0 | R30: =Bobot!$P30*($I30*('Input Bank'!$K30+'Input Bank'!$L30)/30)+($J30*'Input Bank'!R30) -> 0 | S30: =Bobot!$P30*($I30*('Input Bank'!$K30+'Input Bank'!$L30)/30)+($J30*'Input Bank'!S30) -> 0 | T30: =Bobot!$P30*($I30*('Input Bank'!$K30+'Input Bank'!$L30)/30)+($J30*'Input Bank'!T30) -> 0 | ... AP30: =Bobot!$P30*($I30*('Input Bank'!$K30+'Input Bank'!$L30)/30)+($J30*'Input Bank'!AP30) -> 0 | AQ30: =$J30*'Input Bank'!AQ30 -> 0 | AR30: =$J30*'Input Bank'!AR30 -> 0 | AS30: =$J30*'Input Bank'!AS30 -> 0 | AT30: =$J30*'Input Bank'!AT30 -> 0 | AU30: =$J30*'Input Bank'!AU30 -> 0 | AV30: =$J30*'Input Bank'!AV30 -> 0 | AW30: =$J30*'Input Bank'!AW30 -> 0 | AX30: =$J30*'Input Bank'!AX30 -> 0 | ... BA30: =$J30*'Input Bank'!BA30 -> 0
A31: =Bobot!P31 -> 0 | F31: 018 | G31: 1.2 | H31: Kewajiban terkait efek yang diterbitkan | L31: =SUM(L32:L33) -> 0 | M31: =SUM(M32:M33) -> 0 | N31: =SUM(N32:N33) -> 0 | O31: =SUM(O32:O33) -> 0 | P31: =SUM(P32:P33) -> 0 | Q31: =SUM(Q32:Q33) -> 0 | R31: =SUM(R32:R33) -> 0 | S31: =SUM(S32:S33) -> 0 | ... BA31: =SUM(BA32:BA33) -> 0
A32: =Bobot!P32 -> 0 | F32: 019 | G32: 1.2.1 | H32: Surat berharga berupa surat utang yang diterbitkan Bank tanpa agunan | I32: =Bobot!O32 -> 1 | J32: =Bobot!O32 -> 1 | M32: =$J32*'Input Bank'!M32 -> 0 | N32: =$J32*'Input Bank'!N32 -> 0 | O32: =$J32*'Input Bank'!O32 -> 0 | P32: =$J32*'Input Bank'!P32 -> 0 | Q32: =$J32*'Input Bank'!Q32 -> 0 | R32: =$J32*'Input Bank'!R32 -> 0 | S32: =$J32*'Input Bank'!S32 -> 0 | T32: =$J32*'Input Bank'!T32 -> 0 | ... BA32: =$J32*'Input Bank'!BA32 -> 0
A33: =Bobot!#REF! -> #REF! | F33: 020 | G33: 1.2.2 | H33: Lainnya | I33: =Bobot!O33 -> 1 | J33: =Bobot!O33 -> 1 | M33: =$J33*'Input Bank'!M33 -> 0 | N33: =$J33*'Input Bank'!N33 -> 0 | O33: =$J33*'Input Bank'!O33 -> 0 | P33: =$J33*'Input Bank'!P33 -> 0 | Q33: =$J33*'Input Bank'!Q33 -> 0 | R33: =$J33*'Input Bank'!R33 -> 0 | S33: =$J33*'Input Bank'!S33 -> 0 | T33: =$J33*'Input Bank'!T33 -> 0 | ... BA33: =$J33*'Input Bank'!BA33 -> 0
F34: 021 | G34: 1.3 | H34: Pendanaan dengan agunan (secured funding) | L34: =SUM(L35,L42) -> 0 | M34: =SUM(M35,M42) -> 0 | N34: =SUM(N35,N42) -> 0 | O34: =SUM(O35,O42) -> 0 | P34: =SUM(P35,P42) -> 0 | Q34: =SUM(Q35,Q42) -> 0 | R34: =SUM(R35,R42) -> 0 | S34: =SUM(S35,S42) -> 0 | ... BA34: =SUM(BA35,BA42) -> 0
A35: =Bobot!#REF! -> #REF! | F35: 022 | G35: 1.3.1 | H35: Kewajiban timbul dari secured funding atau transaksi pasar modal dengan pihak lawan selain Bank Indonesia: | L35: =SUM(L36:L41) -> 0 | M35: =SUM(M36:M41) -> 0 | N35: =SUM(N36:N41) -> 0 | O35: =SUM(O36:O41) -> 0 | P35: =SUM(P36:P41) -> 0 | Q35: =SUM(Q36:Q41) -> 0 | R35: =SUM(R36:R41) -> 0 | S35: =SUM(S36:S41) -> 0 | ... BA35: =SUM(BA36:BA41) -> 0
A36: =Bobot!P33 -> 0 | F36: 023 | G36: 1.3.2 | H36: Transaksi dilakukan dengan agunan HQLA Level 1 | I36: =Bobot!O36 -> 0 | J36: =Bobot!O36 -> 0 | L36: =IF(Bobot!$P36=0,1,0)*('Input Bank'!L36+'Input Bank'!K36)*I36 -> 0 | M36: =Bobot!$P36*($I36*('Input Bank'!$K36+'Input Bank'!$L36)/30)+($J36*'Input Bank'!M36) -> 0 | N36: =Bobot!$P36*($I36*('Input Bank'!$K36+'Input Bank'!$L36)/30)+($J36*'Input Bank'!N36) -> 0 | O36: =Bobot!$P36*($I36*('Input Bank'!$K36+'Input Bank'!$L36)/30)+($J36*'Input Bank'!O36) -> 0 | P36: =Bobot!$P36*($I36*('Input Bank'!$K36+'Input Bank'!$L36)/30)+($J36*'Input Bank'!P36) -> 0 | Q36: =Bobot!$P36*($I36*('Input Bank'!$K36+'Input Bank'!$L36)/30)+($J36*'Input Bank'!Q36) -> 0 | R36: =Bobot!$P36*($I36*('Input Bank'!$K36+'Input Bank'!$L36)/30)+($J36*'Input Bank'!R36) -> 0 | S36: =Bobot!$P36*($I36*('Input Bank'!$K36+'Input Bank'!$L36)/30)+($J36*'Input Bank'!S36) -> 0 | T36: =Bobot!$P36*($I36*('Input Bank'!$K36+'Input Bank'!$L36)/30)+($J36*'Input Bank'!T36) -> 0 | ... AP36: =Bobot!$P36*($I36*('Input Bank'!$K36+'Input Bank'!$L36)/30)+($J36*'Input Bank'!AP36) -> 0 | AQ36: =$J36*'Input Bank'!AQ36 -> 0 | AR36: =$J36*'Input Bank'!AR36 -> 0 | AS36: =$J36*'Input Bank'!AS36 -> 0 | AT36: =$J36*'Input Bank'!AT36 -> 0 | AU36: =$J36*'Input Bank'!AU36 -> 0 | AV36: =$J36*'Input Bank'!AV36 -> 0 | AW36: =$J36*'Input Bank'!AW36 -> 0 | AX36: =$J36*'Input Bank'!AX36 -> 0 | ... BA36: =$J36*'Input Bank'!BA36 -> 0
A37: =Bobot!P34 -> 0 | F37: 024 | G37: 1.3.3 | H37: Transaksi dilakukan dengan agunan HQLA Level 2A | I37: =Bobot!O37 -> 0.15 | J37: =Bobot!O37 -> 0.15 | L37: =IF(Bobot!$P37=0,1,0)*('Input Bank'!L37+'Input Bank'!K37)*I37 -> 0 | M37: =Bobot!$P37*($I37*('Input Bank'!$K37+'Input Bank'!$L37)/30)+($J37*'Input Bank'!M37) -> 0 | N37: =Bobot!$P37*($I37*('Input Bank'!$K37+'Input Bank'!$L37)/30)+($J37*'Input Bank'!N37) -> 0 | O37: =Bobot!$P37*($I37*('Input Bank'!$K37+'Input Bank'!$L37)/30)+($J37*'Input Bank'!O37) -> 0 | P37: =Bobot!$P37*($I37*('Input Bank'!$K37+'Input Bank'!$L37)/30)+($J37*'Input Bank'!P37) -> 0 | Q37: =Bobot!$P37*($I37*('Input Bank'!$K37+'Input Bank'!$L37)/30)+($J37*'Input Bank'!Q37) -> 0 | R37: =Bobot!$P37*($I37*('Input Bank'!$K37+'Input Bank'!$L37)/30)+($J37*'Input Bank'!R37) -> 0 | S37: =Bobot!$P37*($I37*('Input Bank'!$K37+'Input Bank'!$L37)/30)+($J37*'Input Bank'!S37) -> 0 | T37: =Bobot!$P37*($I37*('Input Bank'!$K37+'Input Bank'!$L37)/30)+($J37*'Input Bank'!T37) -> 0 | ... AP37: =Bobot!$P37*($I37*('Input Bank'!$K37+'Input Bank'!$L37)/30)+($J37*'Input Bank'!AP37) -> 0 | AQ37: =$J37*'Input Bank'!AQ37 -> 0 | AR37: =$J37*'Input Bank'!AR37 -> 0 | AS37: =$J37*'Input Bank'!AS37 -> 0 | AT37: =$J37*'Input Bank'!AT37 -> 0 | AU37: =$J37*'Input Bank'!AU37 -> 0 | AV37: =$J37*'Input Bank'!AV37 -> 0 | AW37: =$J37*'Input Bank'!AW37 -> 0 | AX37: =$J37*'Input Bank'!AX37 -> 0 | ... BA37: =$J37*'Input Bank'!BA37 -> 0
F38: 025 | G38: 1.3.4 | H38: Transaksi dilakukan dengan Pemerintah Pusat atau entitas sektor publik yang memiliki bobot risiko paling tinggi 20% atau bank pembangunan multilateral, dengan agunan selain HQLA Level 1 atau HQLA Level 2A | I38: =Bobot!O38 -> 0.25 | J38: =Bobot!O38 -> 0.25 | L38: =IF(Bobot!$P38=0,1,0)*('Input Bank'!L38+'Input Bank'!K38)*I38 -> 0 | M38: =Bobot!$P38*($I38*('Input Bank'!$K38+'Input Bank'!$L38)/30)+($J38*'Input Bank'!M38) -> 0 | N38: =Bobot!$P38*($I38*('Input Bank'!$K38+'Input Bank'!$L38)/30)+($J38*'Input Bank'!N38) -> 0 | O38: =Bobot!$P38*($I38*('Input Bank'!$K38+'Input Bank'!$L38)/30)+($J38*'Input Bank'!O38) -> 0 | P38: =Bobot!$P38*($I38*('Input Bank'!$K38+'Input Bank'!$L38)/30)+($J38*'Input Bank'!P38) -> 0 | Q38: =Bobot!$P38*($I38*('Input Bank'!$K38+'Input Bank'!$L38)/30)+($J38*'Input Bank'!Q38) -> 0 | R38: =Bobot!$P38*($I38*('Input Bank'!$K38+'Input Bank'!$L38)/30)+($J38*'Input Bank'!R38) -> 0 | S38: =Bobot!$P38*($I38*('Input Bank'!$K38+'Input Bank'!$L38)/30)+($J38*'Input Bank'!S38) -> 0 | T38: =Bobot!$P38*($I38*('Input Bank'!$K38+'Input Bank'!$L38)/30)+($J38*'Input Bank'!T38) -> 0 | ... AP38: =Bobot!$P38*($I38*('Input Bank'!$K38+'Input Bank'!$L38)/30)+($J38*'Input Bank'!AP38) -> 0 | AQ38: =$J38*'Input Bank'!AQ38 -> 0 | AR38: =$J38*'Input Bank'!AR38 -> 0 | AS38: =$J38*'Input Bank'!AS38 -> 0 | AT38: =$J38*'Input Bank'!AT38 -> 0 | AU38: =$J38*'Input Bank'!AU38 -> 0 | AV38: =$J38*'Input Bank'!AV38 -> 0 | AW38: =$J38*'Input Bank'!AW38 -> 0 | AX38: =$J38*'Input Bank'!AX38 -> 0 | ... BA38: =$J38*'Input Bank'!BA38 -> 0
A39: =Bobot!P36 -> 0 | F39: 026 | G39: 1.3.5 | H39: Transaksi dilakukan dengan agunan HQLA Level 2B berupa EBA | I39: =Bobot!O39 -> 0.25 | J39: =Bobot!O39 -> 0.25 | L39: =IF(Bobot!$P39=0,1,0)*('Input Bank'!L39+'Input Bank'!K39)*I39 -> 0 | M39: =Bobot!$P39*($I39*('Input Bank'!$K39+'Input Bank'!$L39)/30)+($J39*'Input Bank'!M39) -> 0 | N39: =Bobot!$P39*($I39*('Input Bank'!$K39+'Input Bank'!$L39)/30)+($J39*'Input Bank'!N39) -> 0 | O39: =Bobot!$P39*($I39*('Input Bank'!$K39+'Input Bank'!$L39)/30)+($J39*'Input Bank'!O39) -> 0 | P39: =Bobot!$P39*($I39*('Input Bank'!$K39+'Input Bank'!$L39)/30)+($J39*'Input Bank'!P39) -> 0 | Q39: =Bobot!$P39*($I39*('Input Bank'!$K39+'Input Bank'!$L39)/30)+($J39*'Input Bank'!Q39) -> 0 | R39: =Bobot!$P39*($I39*('Input Bank'!$K39+'Input Bank'!$L39)/30)+($J39*'Input Bank'!R39) -> 0 | S39: =Bobot!$P39*($I39*('Input Bank'!$K39+'Input Bank'!$L39)/30)+($J39*'Input Bank'!S39) -> 0 | T39: =Bobot!$P39*($I39*('Input Bank'!$K39+'Input Bank'!$L39)/30)+($J39*'Input Bank'!T39) -> 0 | ... AP39: =Bobot!$P39*($I39*('Input Bank'!$K39+'Input Bank'!$L39)/30)+($J39*'Input Bank'!AP39) -> 0 | AQ39: =$J39*'Input Bank'!AQ39 -> 0 | AR39: =$J39*'Input Bank'!AR39 -> 0 | AS39: =$J39*'Input Bank'!AS39 -> 0 | AT39: =$J39*'Input Bank'!AT39 -> 0 | AU39: =$J39*'Input Bank'!AU39 -> 0 | AV39: =$J39*'Input Bank'!AV39 -> 0 | AW39: =$J39*'Input Bank'!AW39 -> 0 | AX39: =$J39*'Input Bank'!AX39 -> 0 | ... BA39: =$J39*'Input Bank'!BA39 -> 0
A40: =Bobot!#REF! -> #REF! | F40: 027 | G40: 1.3.6 | H40: Transaksi dilakukan dengan agunan HQLA Level 2B berupa selain EBA | I40: =Bobot!O40 -> 0.5 | J40: =Bobot!O40 -> 0.5 | L40: =IF(Bobot!$P40=0,1,0)*('Input Bank'!L40+'Input Bank'!K40)*I40 -> 0 | M40: =Bobot!$P40*($I40*('Input Bank'!$K40+'Input Bank'!$L40)/30)+($J40*'Input Bank'!M40) -> 0 | N40: =Bobot!$P40*($I40*('Input Bank'!$K40+'Input Bank'!$L40)/30)+($J40*'Input Bank'!N40) -> 0 | O40: =Bobot!$P40*($I40*('Input Bank'!$K40+'Input Bank'!$L40)/30)+($J40*'Input Bank'!O40) -> 0 | P40: =Bobot!$P40*($I40*('Input Bank'!$K40+'Input Bank'!$L40)/30)+($J40*'Input Bank'!P40) -> 0 | Q40: =Bobot!$P40*($I40*('Input Bank'!$K40+'Input Bank'!$L40)/30)+($J40*'Input Bank'!Q40) -> 0 | R40: =Bobot!$P40*($I40*('Input Bank'!$K40+'Input Bank'!$L40)/30)+($J40*'Input Bank'!R40) -> 0 | S40: =Bobot!$P40*($I40*('Input Bank'!$K40+'Input Bank'!$L40)/30)+($J40*'Input Bank'!S40) -> 0 | T40: =Bobot!$P40*($I40*('Input Bank'!$K40+'Input Bank'!$L40)/30)+($J40*'Input Bank'!T40) -> 0 | ... AP40: =Bobot!$P40*($I40*('Input Bank'!$K40+'Input Bank'!$L40)/30)+($J40*'Input Bank'!AP40) -> 0 | AQ40: =$J40*'Input Bank'!AQ40 -> 0 | AR40: =$J40*'Input Bank'!AR40 -> 0 | AS40: =$J40*'Input Bank'!AS40 -> 0 | AT40: =$J40*'Input Bank'!AT40 -> 0 | AU40: =$J40*'Input Bank'!AU40 -> 0 | AV40: =$J40*'Input Bank'!AV40 -> 0 | AW40: =$J40*'Input Bank'!AW40 -> 0 | AX40: =$J40*'Input Bank'!AX40 -> 0 | ... BA40: =$J40*'Input Bank'!BA40 -> 0
A41: =Bobot!#REF! -> #REF! | F41: 028 | G41: 1.3.7 | H41: Transaksi dilakukan dengan agunan selain HQLA | I41: =Bobot!O41 -> 1 | J41: =Bobot!O41 -> 1 | L41: =IF(Bobot!$P41=0,1,0)*('Input Bank'!L41+'Input Bank'!K41)*I41 -> 0 | M41: =Bobot!$P41*($I41*('Input Bank'!$K41+'Input Bank'!$L41)/30)+($J41*'Input Bank'!M41) -> 0 | N41: =Bobot!$P41*($I41*('Input Bank'!$K41+'Input Bank'!$L41)/30)+($J41*'Input Bank'!N41) -> 0 | O41: =Bobot!$P41*($I41*('Input Bank'!$K41+'Input Bank'!$L41)/30)+($J41*'Input Bank'!O41) -> 0 | P41: =Bobot!$P41*($I41*('Input Bank'!$K41+'Input Bank'!$L41)/30)+($J41*'Input Bank'!P41) -> 0 | Q41: =Bobot!$P41*($I41*('Input Bank'!$K41+'Input Bank'!$L41)/30)+($J41*'Input Bank'!Q41) -> 0 | R41: =Bobot!$P41*($I41*('Input Bank'!$K41+'Input Bank'!$L41)/30)+($J41*'Input Bank'!R41) -> 0 | S41: =Bobot!$P41*($I41*('Input Bank'!$K41+'Input Bank'!$L41)/30)+($J41*'Input Bank'!S41) -> 0 | T41: =Bobot!$P41*($I41*('Input Bank'!$K41+'Input Bank'!$L41)/30)+($J41*'Input Bank'!T41) -> 0 | ... AP41: =Bobot!$P41*($I41*('Input Bank'!$K41+'Input Bank'!$L41)/30)+($J41*'Input Bank'!AP41) -> 0 | AQ41: =$J41*'Input Bank'!AQ41 -> 0 | AR41: =$J41*'Input Bank'!AR41 -> 0 | AS41: =$J41*'Input Bank'!AS41 -> 0 | AT41: =$J41*'Input Bank'!AT41 -> 0 | AU41: =$J41*'Input Bank'!AU41 -> 0 | AV41: =$J41*'Input Bank'!AV41 -> 0 | AW41: =$J41*'Input Bank'!AW41 -> 0 | AX41: =$J41*'Input Bank'!AX41 -> 0 | ... BA41: =$J41*'Input Bank'!BA41 -> 0
F42: 029 | G42: 1.3.8 | H42: Kewajiban timbul dari secured funding atau transaksi pasar modal dengan Bank Indonesia sebagai pihak lawan: | L42: =SUM(L43:L47) -> 0 | M42: =SUM(M43:M47) -> 0 | N42: =SUM(N43:N47) -> 0 | O42: =SUM(O43:O47) -> 0 | P42: =SUM(P43:P47) -> 0 | Q42: =SUM(Q43:Q47) -> 0 | R42: =SUM(R43:R47) -> 0 | S42: =SUM(S43:S47) -> 0 | ... BA42: =SUM(BA43:BA47) -> 0
